Workbook

Sheet Mass Sheet
A1: Item | B1: Description | C1: Weight (lbs) | D1: position from nose (x) (in) | E1: position from nose (y) (in) | F1: position from nose (z) (in) | G1: Reference Fuselage Location [x_i,x_end] (in) | H1: Type | I1: Additional Notes | J1: W*X
A2: M1 | B2: Motor for FWD LH Rotor | C2: 0.85539358 | D2: 23.09 | E2: 3.94 | F2: 18.31 | G2: Avionics Bay [0,31] | H2: Propulsion System | J2: =C2*D2 -> 19.751038
A3: M2 | B3: Motor for FWD RH Rotor | C3: 0.85539358 | D3: 23.09 | E3: 3.94 | F3: -18.31 | G3: Avionics Bay [0,31] | H3: Propulsion System | J3: =C3*D3 -> 19.751038
A4: M3 | B4: Motor for AFT LH Rotor | C4: 0.85539358 | D4: 59.72 | E4: 3.94 | F4: 18.31 | G4: Tail [51.62,95.61] | H4: Propulsion System | J4: =C4*D4 -> 51.084105
A5: M4 | B5: Motor for AFT RH Rotor | C5: 0.85539358 | D5: 59.72 | E5: 3.94 | F5: -18.31 | G5: Tail [51.62,95.61] | H5: Propulsion System | J5: =C5*D5 -> 51.084105
A6: R1 | B6: FWD LH Rotor | C6: 0.09479877 | D6: 23.09 | E6: 3.94 | F6: 18.31 | G6: Avionics Bay [0,31] | H6: Propulsion System | J6: =C6*D6 -> 2.1889036
A7: R2 | B7: FWD RH Rotor | C7: 0.09479877 | D7: 23.09 | E7: 3.94 | F7: -18.31 | G7: Avionics Bay [0,31] | H7: Propulsion System | J7: =C7*D7 -> 2.1889036
A8: R3 | B8: AFT LH Rotor | C8: 0.09479877 | D8: 59.72 | E8: 3.94 | F8: 18.31 | G8: Tail [51.62,95.61] | H8: Propulsion System | J8: =C8*D8 -> 5.6613825
A9: R4 | B9: AFT RH Rotor | C9: 0.09479877 | D9: 59.72 | E9: 3.94 | F9: -18.31 | G9: Tail [51.62,95.61] | H9: Propulsion System | J9: =C9*D9 -> 5.6613825
A10: ESC1 | B10: Electronic Speed Controller 1: Sends Power to M1 | C10: 0.24250849 | D10: 50 | E10: 0 | F10: 0 | G10: Avionics Bay [0,31] | H10: Propulsion System | J10: =C10*D10 -> 12.125424
A11: ESC2 | B11: Electronic Speed Controller 2: Sends Power to M2 | C11: 0.24250849 | D11: 50 | E11: 0 | F11: 0 | G11: Avionics Bay [0,31] | H11: Propulsion System | J11: =C11*D11 -> 12.125424
A12: ESC3 | B12: Electronic Speed Controller 3: Sends Power to M3 | C12: 0.24250849 | D12: 50 | E12: 0 | F12: 0 | G12: Avionics Bay [0,31] | H12: Propulsion System | J12: =C12*D12 -> 12.125424
A13: ESC4 | B13: Electronic Speed Controller 4: Sends Power to M4 | C13: 0.24250849 | D13: 50 | E13: 0 | F13: 0 | G13: Avionics Bay [0,31] | H13: Propulsion System | J13: =C13*D13 -> 12.125424
A14: B1 | B14: Battery 1: S10 (37.0 / 42.0 Volts) | C14: 3.1 | D14: 14 | E14: 0 | F14: 0 | G14: Avionics Bay [0,31] | H14: Energy Storge | I14: Open to moving to AFT Avi bay as req Subject to change | J14: =C14*D14 -> 43.4
A15: B2 | B15: Battery 2: S10 (37.0 / 42.0 Volts) | C15: 3.1 | D15: 25 | E15: 0 | F15: 0 | G15: Avionics Bay [0,31] | H15: Energy Storge | I15: Subject to change | J15: =C15*D15 -> 77.5
A16: HP1 | B16: Hard point 1: FWD ordinance | C16: 3.3069339 | D16: 34.75 | E16: -0.5 | F16: 0 | G16: Payload Bay [31,51.62] | H16: Payload | J16: =C16*D16 -> 114.91595
A17: HP2 | B17: Hard point 2: AFT ordinance | C17: 3.3069339 | D17: 41.25 | E17: -0.5 | F17: 0 | G17: Payload Bay [31,51.62] | H17: Payload | J17: =C17*D17 -> 136.41102
A18: FLIR T | B18: Forward looking Infrared turret | C18: 0.25794085 | D18: 6 | E18: -0.5 | F18: 0 | G18: Avionics Bay [0,31] | H18: Mission Control System | J18: =C18*D18 -> 1.5476451
A19: FC | B19: Flight controller | C19: 0.0838 | D19: 8 | E19: 0 | F19: 0 | G19: Avionics Bay [0,31] | H19: Flight Control System | J19: =C19*D19 -> 0.6704
A20: MC | B20: Mission Controller | C20: 0.1014 | D20: 8 | E20: 0 | F20: 0 | G20: Avionics Bay [0,31] | H20: Mission Control System | J20: =C20*D20 -> 0.8112
A21: HPA1 | B21: Hard Point Actuator Solenoid 1 | C21: 0.353 | D21: 38 | E21: -2.3 | F21: 0 | G21: Payload Bay [31,51.62] | H21: Mission Control System | I21: Subject to change | J21: =C21*D21 -> 13.414
A22: HPA2 | B22: Hard Point Actuator Solenoid 2 | C22: 0.353 | D22: 38 | E22: -2.3 | F22: 0 | G22: Payload Bay [31,51.62] | H22: Mission Control System | J22: =C22*D22 -> 13.414
A23: AIRDATA | B23: Air speed indicator | C23: 0.0077 | D23: 4 | E23: 0 | F23: -1.75 | G23: Avionics Bay [0,31] | H23: Flight Control System | J23: =C23*D23 -> 0.0308
A24: CS3 | B24: LH V-tail Control Servo | C24: 0.1433 | D24: 83.5 | E24: 3.63 | F24: 0 | G24: Tail [51.62,95.61] | H24: Flight Control System | J24: =C24*D24 -> 11.96555
A25: CS4 | B25: RH V-tail Control Servo | C25: 0.1433 | D25: 83.5 | E25: 3.63 | F25: 0 | G25: Tail [51.62,95.61] | H25: Flight Control System | J25: =C25*D25 -> 11.96555
A26: CS1 | B26: LH Aileron Control Servo | C26: 0.1433 | D26: 42.31 | E26: 3.72 | F26: 25 | G26: Payload Bay [31,51.62] | H26: Flight Control System | J26: =C26*D26 -> 6.063023
A27: CS2 | B27: RH Aileron Control Servo | C27: 0.1433 | D27: 42.31 | E27: 3.72 | F27: -25 | G27: Payload Bay [31,51.62] | H27: Flight Control System | J27: =C27*D27 -> 6.063023
A28: EN3 | B28: LH AFT Motor Conversion Encoder | C28: 0.0066 | D28: 59.72 | E28: 3.94 | F28: 18.31 | G28: Tail [51.62,95.61] | H28: Flight Control System | I28: Very subject to change | J28: =C28*D28 -> 0.394152
A29: EN4 | B29: RH AFT Motor Conversion Encoder | C29: 0.0066 | D29: 59.72 | E29: 3.94 | F29: -18.31 | G29: Tail [51.62,95.61] | H29: Flight Control System | I29: Very subject to change | J29: =C29*D29 -> 0.394152
A30: CA3 | B30: LH AFT Motor Conversion Servo | C30: 0.1433 | D30: 59.72 | E30: 3.94 | F30: 18.31 | G30: Tail [51.62,95.61] | H30: Flight Control System | J30: =C30*D30 -> 8.557876
A31: CA4 | B31: LR AFT Motor Conversion Servo | C31: 0.1433 | D31: 59.72 | E31: 3.94 | F31: -18.31 | G31: Tail [51.62,95.61] | H31: Flight Control System | J31: =C31*D31 -> 8.557876
A32: GPS | B32: GPS | C32: 0.0154 | D32: 20 | E32: 2.5 | F32: 0 | G32: Tail [51.62,95.61] | H32: Mission Control System | J32: =C32*D32 -> 0.308
A33: AF-CG | B33: Airframe Structure Allocation by Weight | Center of gravity for AF | C33: =55 - SUM(C2:C32) -> 35.370088 | D33: 43.77 | E33: 2.94 | F33: 0 | H33: Airframe Structure | J33: =C33*D33 -> 1548.1487

Sheet Mass Fractions

Sheet Static Satbillity
A1: W & B w/ AF
A2: Reference relative to nose (x0)in | B2: (in) | C2: Notes:
A3: Center of Gravity from nose | B3: =SUM('Mass Sheet'!J2:J33)/SUM('Mass Sheet'!C2:C33) -> 40.189191 | C3: Computed on payload, avionics, & AF
A4: Quarter Chord from nose | B4: 38.2 | C4: Imported from MATLAB
A5: MAC | B5: 12.6254 | C5: Imported from MATLAB
A6: MAC Leading edge | B6: 35.04 | C6: Imported from MATLAB
A7: Neutral Point | B7: 41.31 | C7: Imported from MATLAB
A9: Reference's as % of MAC | B9: (%) | C9: Notes:
A10: CG | B10: =100 * (B3-B6)/B5 -> 40.784383
A11: Neutral Point (NP) | B11: =100 * (B7-B6)/B5 -> 49.661793
A12: Static Margin (SM) | B12: =100 * (B7-B3)/B5 -> 8.8774103 | C12: %SM > 0 → stable (CG ahead of NP) %SM = 0 → neutral %SM < 0 → unstable

Sheet CAD Mass Config
A1: True AF mass w/o Carbon fiber (lbs) | B1: =E3*2 + sum(E4:E8) -> 62.03 | D1: Components W/ Weight reduction
A2: True AF mass w/ Carbon fiber (lbs) | B2: =B1+B13 -> 65.03 | D2: Component | E2: Solid mass (lbs) | F2: Required Printed mass (lbs)
A3: Mass of Carbon Fiber (lbs) | B3: =B2-B1 -> 3 | D3: Wing ends (x2) | E3: 6.8 | F3: =E3*B6 -> 3.5485507
A4: Target AF mass (lbs) | B4: ='Mass Sheet'!C33 -> 35.370088 | D4: Avi Bay | E4: 9.7 | F4: =E4*B6 -> 5.0619032
A5: Target AF mass w/o Carbon fiber (lbs) | B5: =B4-B3 -> 32.370088 | D5: Mid Wing | E5: 15.99 | F5: =E5*B6 -> 8.3443125
A6: Required weight percentage multiplier | B6: =B5/B1 -> 0.52184569 | D6: Payload Bay | E6: 15.11 | F6: =E6*B6 -> 7.8850883
D7: Tail Cone | E7: 2.07 | F7: =E7*B6 -> 1.0802206
D8: Tail Surfaces | E8: 5.56 | F8: =E8*B6 -> 2.901462
A10: Carbon fiber componets (constant mass) | D10: Required Avi point masses (lbs)
A11: Engine Boom (x2) | B11: 0.91 | D11: M1, R1 | E11: ='Mass Sheet'!C2 +'Mass Sheet'!C6 -> 0.95019235
A12: Tail Boom | B12: 1.18 | D12: M2, R2 | E12: ='Mass Sheet'!C7 +'Mass Sheet'!C3 -> 0.95019235
A13: Total | B13: =B11*2 +B12 -> 3 | D13: M3, R3, CA3, EN3 | E13: ='Mass Sheet'!C4+'Mass Sheet'!C8+'Mass Sheet'!C28+'Mass Sheet'!C31 -> 1.1000923
D14: M4, R4, CA4, EN4 | E14: ='Mass Sheet'!C5+'Mass Sheet'!C9+'Mass Sheet'!C29+'Mass Sheet'!C31 -> 1.1000923
D15: AIRDATA | E15: ='Mass Sheet'!C23 -> 0.0077
D16: MC, FC | E16: ='Mass Sheet'!C19+'Mass Sheet'!C20 -> 0.1852
D17: B1 | E17: ='Mass Sheet'!C14 -> 3.1
D18: B2 | E18: ='Mass Sheet'!C15 -> 3.1
D19: ECS1, ECS2, ECS3, ECS4 | E19: ='Mass Sheet'!C10+'Mass Sheet'!C11+'Mass Sheet'!C12+'Mass Sheet'!C13 -> 0.97003396
D20: CS1 | E20: ='Mass Sheet'!C26 -> 0.1433
D21: CS2 | E21: ='Mass Sheet'!C27 -> 0.1433
D22: HPA1, HPA2 | E22: ='Mass Sheet'!C21+'Mass Sheet'!C22 -> 0.706
D23: CS3, CS4 | E23: ='Mass Sheet'!C24+'Mass Sheet'!C25 -> 0.2866
D24: GPS | E24: ='Mass Sheet'!C32 -> 0.0154
D25: FLIR | E25: ='Mass Sheet'!C18 -> 0.25794085

Sheet CAD Static Stabillity
A1: W & B w/ Payload | E1: W & B w/o Payload
A2: Reference relative to nose (x0)in | B2: (in) | C2: Notes: | E2: Reference relative to nose (x0)in | F2: (in) | G2: Notes:
A3: Center of Gravity from nose | B3: 39.09 | C3: Imported from SolidWorks | E3: Center of Gravity from nose | F3: 39.24 | G3: Imported from SolidWorks
A4: Quarter Chord from nose | B4: 38.15635 | C4: Imported from MATLAB | E4: Quarter Chord from nose | F4: =B4 -> 38.15635 | G4: Imported from MATLAB
A5: MAC | B5: 12.6254 | C5: Imported from MATLAB | E5: MAC | F5: =B5 -> 12.6254 | G5: Imported from MATLAB
A6: MAC Leading edge | B6: 35 | C6: Imported from Solidworks | E6: MAC Leading edge | F6: =B6 -> 35 | G6: Imported from Solidworks
A7: Neutral Point | B7: ='CAD output for Dynamic Stabilli'!G9 -> 41.49 | C7: Imported from MATLAB | E7: Neutral Point | F7: =B7 -> 41.49 | G7: Imported from MATLAB
A8: Nose to tail | B8: 78.06 | C8: Imported from Solidworks | E8: Nose to tail | F8: =B8 -> 78.06 | G8: Imported from Solidworks
A9: Reference's as % of MAC | B9: (%) | C9: Notes: | E9: Reference's as % of MAC | F9: (%) | G9: Notes:
A10: CG | B10: =100 * (B3-B6)/B5 -> 32.395013 | E10: CG | F10: =100 * (F3-F6)/F5 -> 33.583094
A11: Neutral Point (NP) | B11: =100 * (B7-B6)/B5 -> 51.404312 | E11: Neutral Point (NP) | F11: =100 * (F7-F6)/F5 -> 51.404312
A12: Static Margin (SM) | B12: =100 * (B7-B3)/B5 -> 19.009299 | C12: %SM > 0 → stable (CG ahead of NP) %SM = 0 → neutral %SM < 0 → unstable | E12: Static Margin (SM) | F12: =100 * (F7-F3)/F5 -> 17.821218 | G12: %SM > 0 → stable (CG ahead of NP) %SM = 0 → neutral %SM < 0 → unstable
B28: Static Margin shift after Payload deployment (%): | C28: =B12-F12 -> 1.1880812 | D28: (To the aft)
A29: Mass properties of CoDR_Assem_CG | E29: Mass properties of CoDR_Assem_CG
A30: Configuration: Default | E30: Configuration: Default
A31: Coordinate system: Drone Coordinate System | E31: Coordinate system: Drone Coordinate System
A33: * Includes the mass properties of one or more hidden components/bodies. | E33: * Includes the mass properties of one or more hidden components/bodies.
A35: Mass = 55.03 pounds | E35: Mass = 48.42 pounds
A37: Volume = 1690.52 cubic inches | E37: Volume = 1475.47 cubic inches
A39: Surface area = 7882.78 square inches | E39: Surface area = 7650.82 square inches
A41: Center of mass: ( inches ) | E41: Center of mass: ( inches )
B42: X = 39.10 | F42: X = 39.24
B43: Y = 1.76 | F43: Y = 2.07
B44: Z = 0.00 | F44: Z = 0.00
A46: Principal axes of inertia and principal moments of inertia: ( pounds * square inches ) | E46: Principal axes of inertia and principal moments of inertia: ( pounds * square inches )
A47: Taken at the center of mass. | E47: Taken at the center of mass.
B48: Ix = ( 1.00, 0.09, 0.00) | C48: Px = 10910.46 | F48: Ix = ( 1.00, 0.09, 0.00) | G48: Px = 10852.00
B49: Iy = ( 0.00, 0.00, -1.00) | C49: Py = 17223.95 | F49: Iy = ( 0.00, 0.00, -1.00) | G49: Py = 17083.55
B50: Iz = (-0.09, 1.00, 0.00) | C50: Pz = 27587.44 | F50: Iz = (-0.09, 1.00, 0.00) | G50: Pz = 27482.59
A52: Moments of inertia: ( pounds * square inches ) | E52: Moments of inertia: ( pounds * square inches )
A53: Taken at the center of mass and aligned with the output coordinate system. (Using positive tensor notation.) | E53: Taken at the center of mass and aligned with the output coordinate system. (Using positive tensor notation.)
B54: Lxx = 11045.51 | C54: Lxy = 1494.69 | D54: Lxz = 0.42 | F54: Lxx = 10984.06 | G54: Lxy = 1476.08 | H54: Lxz = 0.36
B55: Lyx = 1494.69 | C55: Lyy = 27452.38 | D55: Lyz = 0.35 | F55: Lyx = 1476.08 | G55: Lyy = 27350.53 | H55: Lyz = 0.22
B56: Lzx = 0.42 | C56: Lzy = 0.35 | D56: Lzz = 17223.95 | F56: Lzx = 0.36 | G56: Lzy = 0.22 | H56: Lzz = 17083.55
A58: Moments of inertia: ( pounds * square inches ) | E58: Moments of inertia: ( pounds * square inches )
A59: Taken at the output coordinate system. (Using positive tensor notation.) | E59: Taken at the output coordinate system. (Using positive tensor notation.)
B60: Ixx = 11216.09 | C60: Ixy = 5282.52 | D60: Ixz = 2.54 | F60: Ixx = 11191.42 | G60: Ixy = 5408.33 | H60: Ixz = 4.30
B61: Iyx = 5282.52 | C61: Iyy = 111563.35 | D61: Iyz = 0.44 | F61: Iyx = 5408.33 | G61: Iyy = 101919.97 | H61: Iyz = 0.43
B62: Izx = 2.54 | C62: Izy = 0.44 | D62: Izz = 101505.51 | F62: Izx = 4.30 | G62: Izy = 0.43 | H62: Izz = 91860.35
A64: One or more components have overridden mass properties: | E64: One or more components have overridden mass properties:
...

Sheet CAD output for Dynamic Stabilli
A1: Jager Dynamics | F1: Jager Geometry
A2: Mass properties of CoDR_Assem_CG | F2: Length (from Nose) | G2: (in) | H2: (ft)
A3: Configuration: Default | F3: Wing LE | G3: 35 | H3: =G3/12 -> 2.9166667
A4: Coordinate system: Body Axes | F4: WingQC | G4: =G3+'CAD Static Stabillity'!B5*0.25 -> 38.15635 | H4: =G4/12 -> 3.1796958
F5: Tail LE | G5: 78.06 | H5: =G5/12 -> 6.505
A6: * Includes the mass properties of one or more hidden components/bodies. | F6: TailQC | G6: =G5+9.21464*0.25 -> 80.36366 | H6: =G6/12 -> 6.6969717
F7: Center of Gravity | G7: ='CAD Static Stabillity'!B3 -> 39.09 | H7: =G7/12 -> 3.2575
A8: Mass = 55.0313 pounds | F8: Wing chord to CG Delta z | G8: -1.74 | H8: =G8/12 -> -0.145
F9: NP | G9: 41.49 | H9: 3.4575
A10: Volume = 0.9783 cubic feet
A12: Surface area = 54.7415 square feet
A14: Center of mass: ( feet )
B15: X = -3.2579
B16: Y = -0.0001
B17: Z = -0.1467
A19: Principal axes of inertia and principal moments of inertia: ( pounds * square feet )
A20: Taken at the center of mass.
B21: Ix = (-0.9959, -0.0001, -0.0900) | C21: Px = 75.7671
B22: Iy = (-0.0001, 1.0000, 0.0000) | C22: Py = 119.6108
B23: Iz = ( 0.0900, 0.0000, -0.9959) | C23: Pz = 191.5794
A25: Moments of inertia: ( pounds * square feet )
A26: Taken at the center of mass and aligned with the output coordinate system. (Using positive tensor notation.) | E26: Check units!
B27: Lxx = 76.7050 | C27: Lxy = 0.0029 | D27: Lxz = 10.3798
B28: Lyx = 0.0029 | C28: Lyy = 119.6108 | D28: Lyz = 0.0024
B29: Lzx = 10.3798 | C29: Lzy = 0.0024 | D29: Lzz = 190.6415
A31: Moments of inertia: ( pounds * square feet )
A32: Taken at the output coordinate system. (Using positive tensor notation.)
B33: Ixx = 77.8895 | C33: Ixy = 0.0176 | D33: Ixz = 36.6842
B34: Iyx = 0.0176 | C34: Iyy = 704.8994 | D34: Iyz = 0.0031
B35: Izx = 36.6842 | C35: Izy = 0.0031 | D35: Izz = 774.7455
A37: One or more components have overridden mass properties:
B38: Payload_Bay<1><Default>
B39: Mid_Wing_LW<1><Default>
B40: Wing_ends<1><Default>
B41: Wing_ends<2><Default>
B42: FWD_AVI_BAY<1><Default>
B43: Vtail_V8_Cone<2><Default>@Vtail_V8<1><Default>
B44: Vtail_V9_Surface<1><Default>@Vtail_V8<1><Default>
B45: AIRDATA<1><Default>
B46: B1<1><Default>
...

Sheet ✅ Final Dynamic Stabillity Anal
A1: LONGITUDINAL EIGENVALUES | I1: Target:
A2: -1.5573 + 4.5714i
A3: -1.5573 - 4.5714i
A4: -0.0055 + 0.5198i
A5: -0.0055 - 0.5198i
A7: LATERAL EIGENVALUES
A8: -0.1809 + 2.6533i
A9: -0.1809 - 2.6533i
A10: -2.3794 + 0.0000i
A11: 0.1747 + 0.0000i
A13: LONGITUDINAL HANDLING QUALITY
A15: Short Period:
A16: lambda = -1.5573 +4.5714i
... A89: HQ assess = Unstable spiral, faster than nominal Level 1 criterion

Sheet 🎮 Control Sizing
A3: Flight mode | B3: Target angular speed (deg/s) | C3: Ailreon Deflection (deg) | D3: Ruddervator Deflection (Deg) | E3: Tip offset of surface span base | F3: Root offset of surface span base | G3: Chord from TE
A4: ROLL MODE / AILERON | B4: 25 | C4: 9.869 | D4: 0 | E4: 0.86 | F4: 0.6 | G4: 0.85
A5: PITCH MODE / V-TAIL MIX | B5: 6 | C5: 0 | D5: 4.885 | E5: 0.6 | F5: 0.2 | G5: 0.8
A6: YAW MODE / V-TAIL MIX | B6: 10 | C6: 0 | D6: 19.914 | E6: 0.6 | F6: 0.2 | G6: 0.8
